Workbook

Sheet Market Inputs 
B2: Valuation Date: December 31,2024 | G2: BB Credit Spreads
B3: BB Ticker | C3: Term (yr) | D3: Rate (Actual) | E3: NSS | G3: MUR | H3: 0.0406
B4: USOSFRC Curncy | C4: 0.25 | D4: 4.302 | E4: 4.1809202 | G4: EXX | H4: 0.02
B5: USOSFRF Curncy | C5: 0.5 | D5: 4.2495 | E5: 4.1723329 | G5: THA | H5: 0.0296
B6: USOSFR1 Curncy | C6: 1 | D6: 4.17587 | E6: 4.1565362
B7: USOSFR2 Curncy | C7: 2 | D7: 4.0776 | E7: 4.1298237 | G7: Other market instruments
B8: USOSFR3 Curncy | C8: 3 | D8: 4.05455 | E8: 4.1085698 | G8: Exchange rate | H8: 25.7985
B9: USOSFR4 Curncy | C9: 4 | D9: 4.0415 | E9: 4.0917165 | G9: Zimbabwe Country Risk Premium | H9: 0.1202
B10: USOSFR5 Curncy | C10: 5 | D10: 4.0385 | E10: 4.0783986
B11: USOSFR6 Curncy | C11: 6 | D11: 4.0435 | E11: 4.0679101
B12: USOSFR7 Curncy | C12: 7 | D12: 4.04905 | E12: 4.0596751 | G12: Inputs | H12: Values
B13: USOSFR8 Curncy | C13: 8 | D13: 4.05536 | E13: 4.0532251 | G13: B0 | H13: 10.45
B14: USOSFR9 Curncy | C14: 9 | D14: 4.0624 | E14: 4.0481795 | G14: B1 | H14: -6.26
B15: USOSFR10 Curncy | C15: 10 | D15: 4.071 | E15: 4.0442299 | G15: B2 | H15: -13.14
B16: USOSFR15 Curncy | C16: 15 | D16: 4.11888 | E16: 4.0337063 | G16: B3 | H16: -0.36
B17: USOSFR20 Curncy | C17: 20 | D17: 4.1015 | E17: 4.0283129 | G17: T1 | H17: 886.26
B18: USOSFR30 Curncy | C18: 30 | D18: 3.93352 | E18: 4.0143735 | G18: T2 | H18: 5.38
B22: Date | C22: Holiday Name
B23: 45292 | C23: New Year's Day
B24: 45343 | C24: Robert Mugabe National Youth Day
B25: 45380 | C25: Good Friday
B26: 45381 | C26: Easter Saturday
B27: 45382 | C27: Easter Sunday
B28: 45383 | C28: Easter Monday
B29: 45400 | C29: Independence Day
B30: 45413 | C30: Workers' Day
B31: 45437 | C31: Africa Day
B32: 45516 | C32: Heroes' Day
B33: 45517 | C33: Defence Forces Day
B34: 45648 | C34: National Unity Day
... B36: 45652 | C36: Boxing Day
XFD1048550: {=solver_pre} -> 1e-06
XFD1048551: {=solver_scl} -> 1
XFD1048552: {=solver_rlx} -> 2
XFD1048553: {=solver_tol} -> 0.01
XFD1048554: {=solver_cvg} -> 0.0001
XFD1048555: {=solver_msl} -> 2
XFD1048556: {=solver_ssz} -> 100
XFD1048557: {=solver_rsd} -> 0
XFD1048558: {=solver_mrt} -> 0.075
...

Sheet Valuation Summary
C6: SUMMARY OF RESULTS
C8: Corporate Bonds
L10: DURA | N10: OMLAC
C11: Counterparty | D11: Bond Holder | E11: Instrument Type | F11: Issue Date | G11: Maturity Date | H11: Notional Amount | I11: Currency | J11: Coupon/Interest Rate | K11: Coupon Payment Frequency | L11: Present Value | M11: Impairment | N11: Present Value | O11: Impairment
C12: ='Richaw $5m'!D6 -> Richaw | D12: OMLAC | E12: Bond | F12: ='Richaw $5m'!D14 -> 43564 | G12: ='Richaw $5m'!D13 -> 46119 | H12: ='Richaw $5m'!D8 -> 5000000 | I12: USD | J12: ='Richaw $5m'!D10 -> 0.075 | K12: ='Richaw $5m'!D11 -> Semi-annually | L12: ='Richaw $5m'!D29 -> 6910767.9 | M12: ='Richaw $5m'!D31 -> -538675.52 | N12: 7023683.5 | O12: -425759.87
C13: ='Richaw $205k'!D6 -> Richaw | D13: OMLAC | E13: Bond | F13: ='Richaw $205k'!D14 -> 45054 | G13: ='Richaw $205k'!D13 -> 46879 | H13: ='Richaw $205k'!D8 -> 200059.91 | I13: USD | J13: ='Richaw $205k'!D10 -> 0.12 | K13: ='Richaw $205k'!D11 -> Semi-annually | L13: ='Richaw $205k'!D32 -> 216188.46 | M13: ='Richaw $205k'!D34 -> -21497.453 | N13: 185353.62 | O13: -52332.04
C14: =Centragrid!D6 -> Centragrid | D14: OMLAC | E14: Bond | F14: =Centragrid!D15 -> 44833 | G14: =Centragrid!D14 -> 48483 | H14: =Centragrid!D9 -> 18515000 | I14: USD | J14: =Centragrid!D11 -> 0.1 | K14: =Centragrid!D12 -> Semi-annually | L14: =Centragrid!D43 -> 16807947 | M14: =Centragrid!D45 -> -4403458.2 | N14: 16354103 | O14: -4857302.1
C15: =GZH!D6 -> GZH | D15: OMLAC | E15: Bond | F15: =GZH!D15 -> 44825 | G15: =GZH!D14 -> 49205 | H15: =GZH!D9 -> 4280480 | I15: USD | J15: =GZH!D11 -> 0.125 | K15: =GZH!D12 -> Semi-annually | L15: =GZH!D49 -> 6921210.5 | M15: =GZH!D51 -> 1856584.5 | N15: 4044514.3 | O15: -1020111.5
C16: =Nhimbe!D6 -> Nhimbe | D16: OMLAC | E16: Bond | F16: =Nhimbe!D14 -> 44113 | G16: =Nhimbe!D13 -> 45938 | H16: =Nhimbe!D8 -> 2900000 | I16: USD | J16: =Nhimbe!D10 -> 0.07 | K16: =Nhimbe!D11 -> Annually | L16: =Nhimbe!D26 -> 3394859.7 | M16: =Nhimbe!D28 -> -291437.73 | N16: 3461565.2 | O16: -224732.15
C17: ='Solgas $5m'!D6 -> Solgas | D17: OMLAC | E17: Bond | F17: ='Solgas $5m'!D13 -> 43601 | G17: ='Solgas $5m'!D12 -> 46156 | H17: ='Solgas $5m'!D7 -> 5000000.1 | I17: USD | J17: ='Solgas $5m'!D9 -> 0.075 | K17: ='Solgas $5m'!D10 -> Semi-annually | L17: ='Solgas $5m'!D27 -> 6513075.5 | M17: ='Solgas $5m'!D29 -> -577841.24 | N17: 6726235.5 | O17: -364681.3
C18: ='Solgas $518k'!$D$7 -> Solgas | D18: OMLAC | E18: Bond | F18: ='Solgas $518k'!$D$14 -> 44281 | G18: ='Solgas $518k'!$D$13 -> 46836 | H18: ='Solgas $518k'!$D$8 -> 518288 | I18: USD | J18: ='Solgas $518k'!$D$10 -> 0.12 | K18: ='Solgas $518k'!$D$11 -> Semi-annually | L18: ='Solgas $518k'!$D$33 -> 577397.43 | M18: ='Solgas $518k'!$D$35 -> -53694.096 | N18: 402786.75 | O18: -13119.06
C19: ='Glytime '!D6 -> Glytime | D19: OMLAC | E19: Bond | F19: ='Glytime '!D13 -> 45240 | G19: ='Glytime '!D12 -> 47065 | H19: ='Glytime '!D7 -> 900000.08 | I19: USD | J19: ='Glytime '!D9 -> 0.12 | K19: ='Glytime '!D10 -> Semi-annually | L19: ='Glytime '!D32 -> 899113.86 | M19: ='Glytime '!D34 -> -100431.1 | N19: 960777.18 | O19: -38767.79
C20: =Zimcampus!D6 -> Zimcampus | D20: OMLAC | E20: Debt | F20: =Zimcampus!D13 -> 45601 | G20: =Zimcampus!D12 -> 45783.5 | H20: =Zimcampus!D7 -> 200000 | I20: USD | J20: =Zimcampus!D9 -> 0.1 | K20: =Zimcampus!D10 -> Semi-annually | L20: =Zimcampus!D25 -> 197744.32 | M20: =Zimcampus!D27 -> -5324.1668 | N20: 200221.4 | O20: -2847.1
L21: =SUM(L12:L20) -> 42438304 | M21: =SUM(M12:M20) -> -4135775 | N21: =SUM(N12:N20) -> 39359241 | O21: =SUM(O12:O20) -> -6999652.9

Sheet Richaw $5m
C6: Counterparty | D6: Richaw
C7: Valuation Date | D7: 45657
C8: Principal | D8: 5000000
C9: Instrument Type | D9: Bond
C10: Interest Rate | D10: 0.075 | E10: =D8*D10+D12 -> 2824443.4
C11: Interest Pmt Fequency | D11: Semi-annually
C12: Interest Accrued to 31 December 2024 | D12: 2449443.4 | E12: Accrued but unpaid ( Assumed it will be paid equally in the remaining coupon dates)
C13: Maturity Date | D13: =D14+7*365 -> 46119
C14: Issue Date | D14: 43564
C15: Next Coupon Payment Date | D15: =I23 -> 45754
C16: Valuation Date | D16: =D7 -> 45657
C17: Solar companies credit spread | D17: ='Market Inputs '!H5 -> 0.0296 | E17: Bloomberg
C18: Country risk premium | D18: ='Market Inputs '!H9 -> 0.1202 | E18: http://pages.stern.nyu.edu/~adamodar/New_Home_Page/datafile/ctryprem.html
G20: Coupon dates
C21: Term | D21: Interpolated Nelson Seigel-Svenson | E21: Discount rate | F21: CF | G21: PVIF | H21: PV | I21: Coupon Dates | J21: Interest | K21: Accrued Interest Paid | L21: Accrued Interest Balance | M21: Principal | N21: Balance
C22: =(I22-$D$16)/365 -> 0 | I22: =D16 -> 45657 | L22: =D12 -> 2449443.4 | N22: =D8 -> 5000000
C23: =(I23-$D$16)/365 -> 0.26575342 | D23: 0.041803649 | E23: =$D$18+$D$17+D23 -> 0.19160365 | F23: =SUM(J23,K23,M23) -> 2631626.4 | G23: =1/(1+E23)^(C23) -> 0.95448192 | H23: =F23*G23 -> 2511839.8 | I23: =WORKDAY(C42-1, 1, 'Market Inputs '!$B$23:$B$36) -> 45754 | J23: =(I23-I22)/365*$D$10*(N22+L22) -> 148478.63 | K23: =$D$12/3 -> 816481.12 | L23: =L22-K23 -> 1632962.2 | M23: =$N$22/3 -> 1666666.7 | N23: =N22-M23 -> 3333333.3
C24: =(I24-$D$16)/365 -> 0.76438356 | D24: 0.041637594 | E24: =$D$18+$D$17+D24 -> 0.19143759 | F24: =SUM(J24,K24,M24) -> 2668873.6 | G24: =1/(1+E24)^(C24) -> 0.87468635 | H24: =F24*G24 -> 2334427.3 | I24: =WORKDAY(C43-1, 1, 'Market Inputs '!$B$23:$B$36) -> 45936 | J24: =(I24-I23)/365*$D$10*(N23+L23) -> 185725.85 | K24: =$D$12/3 -> 816481.12 | L24: =L23-K24 -> 816481.12 | M24: =$N$22/3 -> 1666666.7 | N24: =N23-M24 -> 1666666.7
C25: =(I25-$D$16)/365 -> 1.2657534 | D25: 0.041488364 | E25: =$D$18+$D$17+D25 -> 0.19128836 | F25: =SUM(J25,K25,M25) -> 2576521 | G25: =1/(1+E25)^(C25) -> 0.80127455 | H25: =F25*G25 -> 2064500.7 | I25: =WORKDAY(C44-1, 1, 'Market Inputs '!$B$23:$B$36) -> 46119 | J25: =(I25-I24)/365*$D$10*(N24+L24) -> 93373.16 | K25: =$D$12/3 -> 816481.12 | L25: =L24-K25 -> 0 | M25: =$N$22/3 -> 1666666.7 | N25: =N24-M25 -> 0
C29: Present Value | D29: =SUM(H23:H25) -> 6910767.9
C30: Carrying Value | D30: =D8+D12 -> 7449443.4
C31: Impairment | D31: =D29-D30 -> -538675.52
D34: USD | E34: Exch rate | F34: ZwG
C35: Fair value | D35: =D29 -> 6910767.9 | E35: ='Market Inputs '!H8 -> 25.7985 | F35: =D35*E35 -> 1.7828744e+08
C36: Carrying value | D36: =D30 -> 7449443.4 | E36: ='Market Inputs '!H8 -> 25.7985 | F36: =D36*E36 -> 1.9218446e+08
F37: =F35-F36 -> -13897020
C41: Interest Payment Dates
C42: =C43-365/2 -> 45754
C43: =C44-365/2 -> 45936.5
C44: =D13 -> 46119

Sheet Richaw $205k
C6: Counterparty | D6: Richaw
C7: Valuation Date | D7: 45657
C8: Principal | D8: 200059.91
C9: Instrument Type | D9: Bond
C10: Interest Rate | D10: 0.12
C11: Interest Pmt Fequency | D11: Semi-annually
C12: ='[1]Richaw $5m'!A12 -> Interest Accrued to 31 December 2024 | D12: 37626 | E12: Accrued but unpaid ( Assumed it will be paid equally in the remaining coupon dates)
C13: Maturity Date | D13: =D14+(5*365) -> 46879
C14: Issue Date | D14: 45054
C15: Next Coupon Payment Date | D15: =I23 -> 45784
C16: Valuation Date | D16: =D7 -> 45657
C17: Solar companies credit spread | D17: ='Market Inputs '!H5 -> 0.0296 | E17: Bloomberg
C18: Country risk premium | D18: ='Market Inputs '!H9 -> 0.1202 | E18: http://pages.stern.nyu.edu/~adamodar/New_Home_Page/datafile/ctryprem.html
J19: century got
C21: Term | D21: Interpolated Nelson Seigel-Svenson | E21: Discount rate | F21: CF | G21: PVIF | H21: PV | I21: Coupon dates | J21: Interest | K21: Accrued Interest | M21: Principal | N21: Balance
C22: =(I22-$D$16)/365 -> 0 | I22: =D16 -> 45657 | L22: =D12 -> 37626 | N22: =D8 -> 200059.91
C23: =(I23-$D$16)/365 -> 0.34794521 | D23: 0.041774986 | E23: =$D$18+$D$17+D23 -> 0.19157499 | F23: =SUM(J23,K23,M23) -> 43879.331 | G23: =1/(1+E23)^(C23) -> 0.94083601 | H23: =F23*G23 -> 41283.254 | I23: =WORKDAY(C44-1, 1, 'Market Inputs '!$B$23:$B$36) -> 45784 | J23: =(I23-I22)/365*$D$10*(N22+L22) -> 9924.2007 | K23: =$D$12/7 -> 5375.1429 | L23: =L22-K23 -> 32250.857 | M23: =$N$22/7 -> 28579.987 | N23: =N22-M23 -> 171479.92
C24: =(I24-$D$16)/365 -> 0.84657534 | D24: 0.041611961 | E24: =$D$18+$D$17+D24 -> 0.19141196 | F24: =SUM(J24,K24,M24) -> 46145.487 | G24: =1/(1+E24)^(C24) -> 0.86219961 | H24: =F24*G24 -> 39786.621 | I24: =WORKDAY(C45-1, 1, 'Market Inputs '!$B$23:$B$36) -> 45966 | J24: =(I24-I23)/365*$D$10*(N23+L23) -> 12190.357 | K24: =$D$12/7 -> 5375.1429 | L24: =L23-K24 -> 26875.714 | M24: =$N$22/7 -> 28579.987 | N24: =N23-M24 -> 142899.94
C25: =(I25-$D$16)/365 -> 1.3479452 | D25: 0.041465472 | E25: =$D$18+$D$17+D25 -> 0.19126547 | F25: =SUM(J25,K25,M25) -> 44169.577 | G25: =1/(1+E25)^(C25) -> 0.78985002 | H25: =F25*G25 -> 34887.342 | I25: =WORKDAY(C46-1, 1, 'Market Inputs '!$B$23:$B$36) -> 46149 | J25: =(I25-I24)/365*$D$10*(N24+L24) -> 10214.447 | K25: =$D$12/7 -> 5375.1429 | L25: =L24-K25 -> 21500.571 | M25: =$N$22/7 -> 28579.987 | N25: =N24-M25 -> 114319.95
C26: =(I26-$D$16)/365 -> 1.8465753 | D26: 0.041335382 | E26: =$D$18+$D$17+D26 -> 0.19113538 | F26: =SUM(J26,K26,M26) -> 42082.035 | G26: =1/(1+E26)^(C26) -> 0.72398915 | H26: =F26*G26 -> 30466.936 | I26: =WORKDAY(C47-1, 1, 'Market Inputs '!$B$23:$B$36) -> 46331 | J26: =(I26-I25)/365*$D$10*(N25+L25) -> 8126.9045 | K26: =$D$12/7 -> 5375.1429 | L26: =L25-K26 -> 16125.429 | M26: =$N$22/7 -> 28579.987 | N26: =N25-M26 -> 85739.961
C27: =(I27-$D$16)/365 -> 2.3479452 | D27: 0.041218677 | E27: =$D$18+$D$17+D27 -> 0.19101868 | F27: =SUM(J27,K27,M27) -> 40083.798 | G27: =1/(1+E27)^(C27) -> 0.66335706 | H27: =F27*G27 -> 26589.87 | I27: =WORKDAY(C48-1, 1, 'Market Inputs '!$B$23:$B$36) -> 46514 | J27: =(I27-I26)/365*$D$10*(N26+L26) -> 6128.6684 | K27: =$D$12/7 -> 5375.1429 | L27: =L26-K27 -> 10750.286 | M27: =$N$22/7 -> 28579.987 | N27: =N26-M27 -> 57159.974
C28: =(I28-$D$16)/365 -> 2.8465753 | D28: 0.041115209 | E28: =$D$18+$D$17+D28 -> 0.19091521 | F28: =SUM(J28,K28,M28) -> 38018.582 | G28: =1/(1+E28)^(C28) -> 0.60813426 | H28: =F28*G28 -> 23120.402 | I28: =WORKDAY(C49-1, 1, 'Market Inputs '!$B$23:$B$36) -> 46696 | J28: =(I28-I27)/365*$D$10*(N27+L27) -> 4063.4523 | K28: =$D$12/7 -> 5375.1429 | L28: =L27-K28 -> 5375.1429 | M28: =$N$22/7 -> 28579.987 | N28: =N27-M28 -> 28579.987
C29: =(I29-$D$16)/365 -> 3.3534247 | D29: 0.041021589 | E29: =$D$18+$D$17+D29 -> 0.19082159 | F29: =SUM(J29,K29,M29) -> 36020.346 | G29: =1/(1+E29)^(C29) -> 0.55674177 | H29: =F29*G29 -> 20054.031 | I29: =WORKDAY(C50-1, 1, 'Market Inputs '!$B$23:$B$36) -> 46881 | J29: =(I29-I28)/365*$D$10*(N28+L28) -> 2065.2161 | K29: =$D$12/7 -> 5375.1429 | L29: =L28-K29 -> 7.2759576e-12 | M29: =$N$22/7 -> 28579.987 | N29: =N28-M29 -> 3.6379788e-11
C32: Present Value | D32: =SUM(H23:H29) -> 216188.46
C33: Carrying Value | D33: =D8+D12 -> 237685.91
C34: Impairment | D34: =D32-D33 -> -21497.453
D37: USD | E37: Exch rate | F37: ZwG
C38: Fair value | D38: =D32 -> 216188.46 | E38: ='Market Inputs '!H8 -> 25.7985 | F38: =D38*E38 -> 5577337.9
C39: Carrying value | D39: =D33 -> 237685.91 | E39: ='Market Inputs '!H8 -> 25.7985 | F39: =D39*E39 -> 6131939.9
F40: =F38-F39 -> -554602.03
C43: Interest Payment Dates
C44: =C45-(365/2) -> 45784 | F44: .
C45: =C46-(365/2) -> 45966.5
C46: =C47-(365/2) -> 46149
C47: =C48-(365/2) -> 46331.5
C48: =C49-(365/2) -> 46514
C49: =C50-(365/2) -> 46696.5
C50: =D13 -> 46879

Sheet Centragrid
C6: Counterparty | D6: Centragrid
C7: Valuation Date | D7: 45657
C8: Committed Capital | D8: 18515000
C9: Principal | D9: 18515000
C10: Instrument Type | D10: Bond
C11: Interest Rate | D11: 0.1
C12: Interest Pmt Fequency | D12: Semi-annually
C13: =[1]GZH!A13 -> Interest Accrued to 31 December 2024 | D13: 2696405 | E13: Accrued but unpaid ( Assumed it will be paid equally in the remaining coupon dates)
C14: Maturity Date | D14: =D15+(10*365) -> 48483
C15: Issue Date | D15: 44833
C16: Next Coupon Payment Date | D16: =C54 -> 45745.5
C17: Valuation Date | D17: =D7 -> 45657
C18: Solar companies credit spread | D18: ='Market Inputs '!H5 -> 0.0296 | E18: Bloomberg
C19: Country risk premium | D19: ='Market Inputs '!H9 -> 0.1202 | E19: http://pages.stern.nyu.edu/~adamodar/New_Home_Page/datafile/ctryprem.html
C22: Term | D22: Interpolated Nelson Seigel-Svenson | E22: Discount rate | F22: CF | G22: PVIF | H22: PV | I22: Coupon Dates | J22: Interest | K22: Accrued Interest Paid | L22: Accrued InterestBalance | M22: Principal | N22: Balance
C23: =(I23-$D$17)/365 -> 0 | I23: =D17 -> 45657 | L23: =D13 -> 2696405 | N23: =D9 -> 18515000
C24: =(I24-$D$17)/365 -> 0.24657534 | D24: 0.041810412 | E24: =$D$19+$D$18+D24 -> 0.19161041 | F24: =SUM(J24,K24,M24) -> 1848733.8 | G24: =(1/(1+$E24))^(C24) -> 0.95769487 | H24: =F24*G24 -> 1770522.8 | I24: =WORKDAY(C54-1, 1, 'Market Inputs '!$B$23:$B$36) -> 45747 | J24: =(I24-I23)/365*$D$11*(N23+L23) -> 523020.95 | K24: =$D$13/16 -> 168525.31 | L24: =L23-K24 -> 2527879.7 | M24: =$N$23/16 -> 1157187.5 | N24: =N23-M24 -> 17357812
C25: =(I25-$D$17)/365 -> 0.74520548 | D25: 0.041643644 | E25: =$D$19+$D$18+D25 -> 0.19144364 | F25: =SUM(J25,K25,M25) -> 2317273.4 | G25: =(1/(1+$E25))^(C25) -> 0.87762626 | H25: =F25*G25 -> 2033699.9 | I25: =WORKDAY(C55-1, 1, 'Market Inputs '!$B$23:$B$36) -> 45929 | J25: =(I25-I24)/365*$D$11*(N24+L24) -> 991560.54 | K25: =$D$13/16 -> 168525.31 | L25: =L24-K25 -> 2359354.4 | M25: =$N$23/16 -> 1157187.5 | N25: =N24-M25 -> 16200625
C26: =(I26-$D$17)/365 -> 1.2438356 | D26: 0.041494541 | E26: =$D$19+$D$18+D26 -> 0.19129454 | F26: =SUM(J26,K26,M26) -> 2251169.3 | G26: =(1/(1+$E26))^(C26) -> 0.80434927 | H26: =F26*G26 -> 1810726.4 | I26: =WORKDAY(C56-1, 1, 'Market Inputs '!$B$23:$B$36) -> 46111 | J26: =(I26-I25)/365*$D$11*(N25+L25) -> 925456.51 | K26: =$D$13/16 -> 168525.31 | L26: =L25-K26 -> 2190829.1 | M26: =$N$23/16 -> 1157187.5 | N26: =N25-M26 -> 15043438
C27: =(I27-$D$17)/365 -> 1.7424658 | D27: 0.041361339 | E27: =$D$19+$D$18+D27 -> 0.19116134 | F27: =SUM(J27,K27,M27) -> 2185065.3 | G27: =(1/(1+$E27))^(C27) -> 0.7372654 | H27: =F27*G27 -> 1610973 | I27: =WORKDAY(C57-1, 1, 'Market Inputs '!$B$23:$B$36) -> 46293 | J27: =(I27-I26)/365*$D$11*(N26+L26) -> 859352.47 | K27: =$D$13/16 -> 168525.31 | L27: =L26-K27 -> 2022303.8 | M27: =$N$23/16 -> 1157187.5 | N27: =N26-M27 -> 13886250
C28: =(I28-$D$17)/365 -> 2.2410959 | D28: 0.041242437 | E28: =$D$19+$D$18+D28 -> 0.19104244 | F28: =SUM(J28,K28,M28) -> 2118961.2 | G28: =(1/(1+$E28))^(C28) -> 0.67583361 | H28: =F28*G28 -> 1432065.2 | I28: =WORKDAY(C58-1, 1, 'Market Inputs '!$B$23:$B$36) -> 46475 | J28: =(I28-I27)/365*$D$11*(N27+L27) -> 793248.43 | K28: =$D$13/16 -> 168525.31 | L28: =L27-K28 -> 1853778.4 | M28: =$N$23/16 -> 1157187.5 | N28: =N27-M28 -> 12729062
C29: =(I29-$D$17)/365 -> 2.7424658 | D29: 0.04113584 | E29: =$D$19+$D$18+D29 -> 0.19093584 | F29: =SUM(J29,K29,M29) -> 2056852.5 | G29: =(1/(1+$E29))^(C29) -> 0.61926817 | H29: =F29*G29 -> 1273743.3 | I29: =WORKDAY(C59-1, 1, 'Market Inputs '!$B$23:$B$36) -> 46658 | J29: =(I29-I28)/365*$D$11*(N28+L28) -> 731139.7 | K29: =$D$13/16 -> 168525.31 | L29: =L28-K29 -> 1685253.1 | M29: =$N$23/16 -> 1157187.5 | N29: =N28-M29 -> 11571875
C30: =(I30-$D$17)/365 -> 3.2410959 | D30: 0.041041396 | E30: =$D$19+$D$18+D30 -> 0.1908414 | F30: =SUM(J30,K30,M30) -> 1986753.2 | G30: =(1/(1+$E30))^(C30) -> 0.56774087 | H30: =F30*G30 -> 1127961 | I30: =WORKDAY(C60-1, 1, 'Market Inputs '!$B$23:$B$36) -> 46840 | J30: =(I30-I29)/365*$D$11*(N29+L29) -> 661040.36 | K30: =$D$13/16 -> 168525.31 | L30: =L29-K30 -> 1516727.8 | M30: =$N$23/16 -> 1157187.5 | N30: =N29-M30 -> 10414688
C31: =(I31-$D$17)/365 -> 3.7424658 | D31: 0.040956871 | E31: =$D$19+$D$18+D31 -> 0.19075687 | F31: =SUM(J31,K31,M31) -> 1923918 | G31: =(1/(1+$E31))^(C31) -> 0.52027704 | H31: =F31*G31 -> 1000970.4 | I31: =WORKDAY(C61-1, 1, 'Market Inputs '!$B$23:$B$36) -> 47023 | J31: =(I31-I30)/365*$D$11*(N30+L30) -> 598205.21 | K31: =$D$13/16 -> 168525.31 | L31: =L30-K31 -> 1348202.5 | M31: =$N$23/16 -> 1157187.5 | N31: =N30-M31 -> 9257500
C32: =(I32-$D$17)/365 -> 4.2410959 | D32: 0.040882113 | E32: =$D$19+$D$18+D32 -> 0.19068211 | F32: =SUM(J32,K32,M32) -> 1854545.1 | G32: =(1/(1+$E32))^(C32) -> 0.47702662 | H32: =F32*G32 -> 884667.39 | I32: =WORKDAY(C62-1, 1, 'Market Inputs '!$B$23:$B$36) -> 47205 | J32: =(I32-I31)/365*$D$11*(N31+L31) -> 528832.29 | K32: =$D$13/16 -> 168525.31 | L32: =L31-K32 -> 1179677.2 | M32: =$N$23/16 -> 1157187.5 | N32: =N31-M32 -> 8100312.5
C33: =(I33-$D$17)/365 -> 4.7424658 | D33: 0.040815321 | E33: =$D$19+$D$18+D33 -> 0.19061532 | F33: =SUM(J33,K33,M33) -> 1790983.5 | G33: =(1/(1+$E33))^(C33) -> 0.4371761 | H33: =F33*G33 -> 782975.2 | I33: =WORKDAY(C63-1, 1, 'Market Inputs '!$B$23:$B$36) -> 47388 | J33: =(I33-I32)/365*$D$11*(N32+L32) -> 465270.72 | K33: =$D$13/16 -> 168525.31 | L33: =L32-K33 -> 1011151.9 | M33: =$N$23/16 -> 1157187.5 | N33: =N32-M33 -> 6943125
C34: =(I34-$D$17)/365 -> 5.2410959 | D34: 0.040756348 | E34: =$D$19+$D$18+D34 -> 0.19055635 | F34: =SUM(J34,K34,M34) -> 1722337 | G34: =(1/(1+$E34))^(C34) -> 0.40085492 | H34: =F34*G34 -> 690407.28 | I34: =WORKDAY(C64-1, 1, 'Market Inputs '!$B$23:$B$36) -> 47570 | J34: =(I34-I33)/365*$D$11*(N33+L33) -> 396624.22 | K34: =$D$13/16 -> 168525.31 | L34: =L33-K34 -> 842626.56 | M34: =$N$23/16 -> 1157187.5 | N34: =N33-M34 -> 5785937.5
C35: =(I35-$D$17)/365 -> 5.7424658 | D35: 0.040703748 | E35: =$D$19+$D$18+D35 -> 0.19050375 | F35: =SUM(J35,K35,M35) -> 1658049 | G35: =(1/(1+$E35))^(C35) -> 0.36738267 | H35: =F35*G35 -> 609138.48 | I35: =WORKDAY(C65-1, 1, 'Market Inputs '!$B$23:$B$36) -> 47753 | J35: =(I35-I34)/365*$D$11*(N34+L34) -> 332336.23 | K35: =$D$13/16 -> 168525.31 | L35: =L34-K35 -> 674101.25 | M35: =$N$23/16 -> 1157187.5 | N35: =N34-M35 -> 4628750
... C39: =(I39-$D$17)/365 -> 7.7452055 | D39: 0.040547215 | E39: =$D$19+$D$18+D39 -> 0.19034721 | F39: =SUM(J39,K39,M39) -> 1391816.8 | G39: =(1/(1+$E39))^(C39) -> 0.2593534 | H39: =F39*G39 -> 360972.44 | I39: =WORKDAY(C69-1, 1, 'Market Inputs '!$B$23:$B$36) -> 48484 | J39: =(I39-I38)/365*$D$11*(N38+L38) -> 66104.036 | K39: =$D$13/16 -> 168525.31 | L39: =L38-K39 -> 0 | M39: =$N$23/16 -> 1157187.5 | N39: =N38-M39 -> 0
C43: Present Value | D43: =SUM(H24:H39) -> 16807947
C44: Carrying Value | D44: =D9+D13 -> 21211405
C45: Impairment | D45: =D43-D44 -> -4403458.2
D47: USD | E47: Exch rate | F47: ZwG
C48: Fair value | D48: =D43 -> 16807947 | E48: ='Market Inputs '!H8 -> 25.7985 | F48: =D48*E48 -> 4.3361982e+08
C49: Carrying value | D49: =D44 -> 21211405 | E49: ='Market Inputs '!H8 -> 25.7985 | F49: =D49*E49 -> 5.4722243e+08
F50: =F48-F49 -> -1.1360262e+08
C53: Interest Payment Dates
C54: =C55-365/2 -> 45745.5
C55: =C56-365/2 -> 45928
C56: =C57-365/2 -> 46110.5
...

Sheet GZH
C6: Counterparty | D6: GZH
C7: Valuation Date | D7: 45657
C8: Committed Capital | D8: =3524080+756400 -> 4280480
C9: Principal ( Amount Deployed) | D9: 4280480
C10: Instrument Type | D10: Bond
C11: Interest Rate | D11: 0.125
C12: Interest Pmt Fequency | D12: Semi-annually
C13: ='[1]Richaw $205k'!A12 -> Interest Accrued to 31 December 2024 | D13: 784146 | E13: Accrued but unpaid ( Assumed it will be paid equally in the remaining coupon dates)
C14: Maturity Date | D14: =D15+(12*365) -> 49205
C15: Issue Date | D15: 44825
C16: Next Coupon Payment Date | D16: =C61 -> 45737.5
C17: Valuation Date | D17: =D7 -> 45657
C18: Future Interest payment Dates | D18: =I43 -> 48659
C19: Remaining payments | D19: 20
C20: Solar companies credit spread | D20: ='Market Inputs '!H5 -> 0.0296 | E20: Bloomberg
C21: Country risk premium | D21: ='Market Inputs '!H9 -> 0.1202 | E21: http://pages.stern.nyu.edu/~adamodar/New_Home_Page/datafile/ctryprem.html
C24: Term | D24: Interpolated Nelson Seigel-Svenson | E24: Discount rate | F24: CF | G24: PVIF | H24: PV | I24: Coupon dates | J24: Interest | K24: Accrued Interest | L24: Accrued Interest Balance Paid | M24: Principal | N24: Balance
C26: =(I26-$D$17)/365 -> 0 | I26: =D17 -> 45657 | L26: =D13 -> 784146 | N26: =D9 -> 4280480
C27: =(I27-$D$17)/365 -> 0.21917808 | D27: 0.041820125 | E27: =$D$21+$D$20+D27 -> 0.19162013 | F27: =SUM(J27,K27,M27) -> 391988.18 | G27: =1/(1+D27)^(C27) -> 0.99106062 | H27: =F27*G27 -> 388484.05 | I27: =WORKDAY(C61-1, 1, 'Market Inputs '!$B$23:$B$36) -> 45737 | J27: =(I27-I26)/365*$D$11*(N26+L26) -> 138756.88 | K27: =$D$13/20 -> 39207.3 | L27: =L26-K27 -> 744938.7 | M27: =$N$26/$D$19 -> 214024 | N27: =N26-M27 -> 4066456
C28: =(I28-$D$17)/365 -> 0.7260274 | D28: 0.041649719 | E28: =$D$21+$D$20+D28 -> 0.19144972 | F28: =SUM(J28,K28,M28) -> 558062.81 | G28: =1/(1+D28)^(C28) -> 0.97080848 | H28: =F28*G28 -> 541772.11 | I28: =WORKDAY(C62-1, 1, 'Market Inputs '!$B$23:$B$36) -> 45922 | J28: =(I28-I27)/365*$D$11*(N27+L27) -> 304831.51 | K28: =$D$13/20 -> 39207.3 | L28: =L27-K28 -> 705731.4 | M28: =$N$26/$D$19 -> 214024 | N28: =N27-M28 -> 3852432
C29: =(I29-$D$17)/365 -> 1.2246575 | D29: 0.041499971 | E29: =$D$21+$D$20+D29 -> 0.19129997 | F29: =SUM(J29,K29,M29) -> 537336.01 | G29: =1/(1+D29)^(C29) -> 0.95142257 | H29: =F29*G29 -> 511233.6 | I29: =WORKDAY(C63-1, 1, 'Market Inputs '!$B$23:$B$36) -> 46104 | J29: =(I29-I28)/365*$D$11*(N28+L28) -> 284104.71 | K29: =$D$13/20 -> 39207.3 | L29: =L28-K29 -> 666524.1 | M29: =$N$26/$D$19 -> 214024 | N29: =N28-M29 -> 3638408
C30: =(I30-$D$17)/365 -> 1.7232877 | D30: 0.041366188 | E30: =$D$21+$D$20+D30 -> 0.19116619 | F30: =SUM(J30,K30,M30) -> 521552.41 | G30: =1/(1+D30)^(C30) -> 0.93253288 | H30: =F30*G30 -> 486364.77 | I30: =WORKDAY(C64-1, 1, 'Market Inputs '!$B$23:$B$36) -> 46286 | J30: =(I30-I29)/365*$D$11*(N29+L29) -> 268321.11 | K30: =$D$13/20 -> 39207.3 | L30: =L29-K30 -> 627316.8 | M30: =$N$26/$D$19 -> 214024 | N30: =N29-M30 -> 3424384
C31: =(I31-$D$17)/365 -> 2.2219178 | D31: 0.041246764 | E31: =$D$21+$D$20+D31 -> 0.19104676 | F31: =SUM(J31,K31,M31) -> 505768.82 | G31: =1/(1+D31)^(C31) -> 0.91410735 | H31: =F31*G31 -> 462326.99 | I31: =WORKDAY(C65-1, 1, 'Market Inputs '!$B$23:$B$36) -> 46468 | J31: =(I31-I30)/365*$D$11*(N30+L30) -> 252537.52 | K31: =$D$13/20 -> 39207.3 | L31: =L30-K31 -> 588109.5 | M31: =$N$26/$D$19 -> 214024 | N31: =N30-M31 -> 3210360
C32: =(I32-$D$17)/365 -> 2.7205479 | D32: 0.041140247 | E32: =$D$21+$D$20+D32 -> 0.19094025 | F32: =SUM(J32,K32,M32) -> 489985.22 | G32: =1/(1+D32)^(C32) -> 0.89611818 | H32: =F32*G32 -> 439084.66 | I32: =WORKDAY(C66-1, 1, 'Market Inputs '!$B$23:$B$36) -> 46650 | J32: =(I32-I31)/365*$D$11*(N31+L31) -> 236753.92 | K32: =$D$13/20 -> 39207.3 | L32: =L31-K32 -> 548902.2 | M32: =$N$26/$D$19 -> 214024 | N32: =N31-M32 -> 2996336
C33: =(I33-$D$17)/365 -> 3.2191781 | D33: 0.041045322 | E33: =$D$21+$D$20+D33 -> 0.19084532 | F33: =SUM(J33,K33,M33) -> 474201.63 | G33: =1/(1+D33)^(C33) -> 0.87854119 | H33: =F33*G33 -> 416605.66 | I33: =WORKDAY(C67-1, 1, 'Market Inputs '!$B$23:$B$36) -> 46832 | J33: =(I33-I32)/365*$D$11*(N32+L32) -> 220970.33 | K33: =$D$13/20 -> 39207.3 | L33: =L32-K33 -> 509694.9 | M33: =$N$26/$D$19 -> 214024 | N33: =N32-M33 -> 2782312
C34: =(I34-$D$17)/365 -> 3.7205479 | D34: 0.040960363 | E34: =$D$21+$D$20+D34 -> 0.19076036 | F34: =SUM(J34,K34,M34) -> 459545.43 | G34: =1/(1+D34)^(C34) -> 0.86126193 | H34: =F34*G34 -> 395788.98 | I34: =WORKDAY(C68-1, 1, 'Market Inputs '!$B$23:$B$36) -> 47015 | J34: =(I34-I33)/365*$D$11*(N33+L33) -> 206314.13 | K34: =$D$13/20 -> 39207.3 | L34: =L33-K34 -> 470487.6 | M34: =$N$26/$D$19 -> 214024 | N34: =N33-M34 -> 2568288
C35: =(I35-$D$17)/365 -> 4.2191781 | D35: 0.040885218 | E35: =$D$21+$D$20+D35 -> 0.19068522 | F35: =SUM(J35,K35,M35) -> 442634.44 | G35: =1/(1+D35)^(C35) -> 0.84445073 | H35: =F35*G35 -> 373782.97 | I35: =WORKDAY(C69-1, 1, 'Market Inputs '!$B$23:$B$36) -> 47197 | J35: =(I35-I34)/365*$D$11*(N34+L34) -> 189403.14 | K35: =$D$13/20 -> 39207.3 | L35: =L34-K35 -> 431280.3 | M35: =$N$26/$D$19 -> 214024 | N35: =N34-M35 -> 2354264
C36: =(I36-$D$17)/365 -> 4.7205479 | D36: 0.040818078 | E36: =$D$21+$D$20+D36 -> 0.19061808 | F36: =SUM(J36,K36,M36) -> 427804.8 | G36: =1/(1+D36)^(C36) -> 0.82790651 | H36: =F36*G36 -> 354182.37 | I36: =WORKDAY(C70-1, 1, 'Market Inputs '!$B$23:$B$36) -> 47380 | J36: =(I36-I35)/365*$D$11*(N35+L35) -> 174573.5 | K36: =$D$13/20 -> 39207.3 | L36: =L35-K36 -> 392073 | M36: =$N$26/$D$19 -> 214024 | N36: =N35-M36 -> 2140240
C37: =(I37-$D$17)/365 -> 5.2191781 | D37: 0.040758795 | E37: =$D$21+$D$20+D37 -> 0.1905588 | F37: =SUM(J37,K37,M37) -> 411067.25 | G37: =1/(1+D37)^(C37) -> 0.81179578 | H37: =F37*G37 -> 333702.66 | I37: =WORKDAY(C71-1, 1, 'Market Inputs '!$B$23:$B$36) -> 47562 | J37: =(I37-I36)/365*$D$11*(N36+L36) -> 157835.95 | K37: =$D$13/20 -> 39207.3 | L37: =L36-K37 -> 352865.7 | M37: =$N$26/$D$19 -> 214024 | N37: =N36-M37 -> 1926216
C38: =(I38-$D$17)/365 -> 5.7205479 | D38: 0.040705917 | E38: =$D$21+$D$20+D38 -> 0.19050592 | F38: =SUM(J38,K38,M38) -> 396064.16 | G38: =1/(1+D38)^(C38) -> 0.79592878 | H38: =F38*G38 -> 315238.86 | I38: =WORKDAY(C72-1, 1, 'Market Inputs '!$B$23:$B$36) -> 47745 | J38: =(I38-I37)/365*$D$11*(N37+L37) -> 142832.86 | K38: =$D$13/20 -> 39207.3 | L38: =L37-K38 -> 313658.4 | M38: =$N$26/$D$19 -> 214024 | N38: =N37-M38 -> 1712192
... C46: =(I46-$D$17)/365 -> 9.7205479 | D46: 0.040452387 | E46: =$D$21+$D$20+D46 -> 0.19025239 | F46: =SUM(J46,K46,M46) -> 269014.89 | G46: =1/(1+D46)^(C46) -> 0.68012803 | H46: =F46*G46 -> 182964.57 | I46: =WORKDAY(C80-1, 1, 'Market Inputs '!$B$23:$B$36) -> 49205 | J46: =(I46-I45)/365*$D$11*(N45+L45) -> 15783.595 | K46: =$D$13/20 -> 39207.3 | L46: =L45-K46 -> -1.7462298e-10 | M46: =$N$26/$D$19 -> 214024 | N46: =N45-M46 -> 0
C49: Present Value | D49: =SUM(H27:H46) -> 6921210.5
C50: Carrying Value | D50: =D9+D13 -> 5064626
C51: Impairment | D51: =D49-D50 -> 1856584.5
D54: USD | E54: Exch rate | F54: ZwG
C55: Fair value | D55: =D49 -> 6921210.5 | E55: ='Market Inputs '!H8 -> 25.7985 | F55: =D55*E55 -> 1.7855685e+08
C56: Carrying value | D56: =D50 -> 5064626 | E56: ='Market Inputs '!H8 -> 25.7985 | F56: =D56*E56 -> 1.3065975e+08
F57: =F55-F56 -> 47897095
C60: Interest Payment Dates
C61: =C62-365/2 -> 45737.5
...

Sheet Nhimbe
C6: Counterparty | D6: Nhimbe
C7: Valuation Date | D7: 45657
C8: Principal | D8: 2900000
C9: Instrument Type | D9: Bond
C10: Interest Rate | D10: 0.07
C11: Interest Pmt Fequency | D11: Annually
C12: Interest Accrued to 30 June 2024 | D12: 679327.95 | E12: Accrued but unpaid ( Assumed it will be paid equally in the remaining coupon dates)
C13: Maturity Date | D13: =D14+(365*5) -> 45938
C14: Issue Date | D14: 44113
C15: Next Coupon Payment Date | D15: =C37 -> 45938
C16: Valuation Date | D16: =D7 -> 45657
C17: Solar companies credit spread | D17: ='Market Inputs '!H5 -> 0.0296 | E17: Bloomberg
C18: Country risk premium | D18: ='Market Inputs '!H9 -> 0.1202 | E18: http://pages.stern.nyu.edu/~adamodar/New_Home_Page/datafile/ctryprem.html
C21: Term | D21: Interpolated Nelson Seigel-Svenson | E21: Discount rate | F21: CF | G21: PVIF | H21: PV | I21: Coupon dates | J21: Interest | K21: Accrued InterestPaid | L21: Accrued Interest Balance | M21: Principal | N21: Balance | O21: Reducing Balance | P21: Capitalised Balance-Equal Instalments
C22: =I22-D16 -> 0 | I22: =D16 -> 45657 | L22: =D12 -> 679327.95 | N22: =D8+P22 -> 3006969.4 | P22: 106969.44
C23: =(I23-D16)/365 -> 0.76986301 | D23: 0.041635871 | E23: =$D$18+$D$17+D23 -> 0.19143587 | F23: =SUM(J23,K23,M23) -> 3884953.5 | G23: =1/(1+E23)^(C23) -> 0.87384822 | H23: =F23*G23 -> 3394859.7 | I23: =WORKDAY(D15-1, 1, 'Market Inputs '!$B$23:$B$36) -> 45938 | J23: =(I23-I22)/365*$D$10*(N22+L22) -> 198656.08 | K23: =$D$12/1 -> 679327.95 | L23: =L22-K23 -> 0 | M23: =N22/1 -> 3006969.4 | N23: =N22-M23 -> 0 | O23: =N22-M23 -> 0
C26: Present Value | D26: =SUM(H23) -> 3394859.7
C27: Carrying Value | D27: =D8+D12+P22 -> 3686297.4
C28: Impairment | D28: =D26-D27 -> -291437.73
F30: USD | G30: =[1]Centragrid!C46 -> Exch rate | H30: ZwG
C31: Fair value | F31: =D26 -> 3394859.7 | G31: ='Market Inputs '!H8 -> 25.7985 | H31: =F31*G31 -> 87582287
C32: Carrying value | F32: =D27 -> 3686297.4 | G32: ='Market Inputs '!H8 -> 25.7985 | H32: =F32*G32 -> 95100943
C33: Impairment | H33: =H31-H32 -> -7518656.3
C36: Interest Payment Dates
C37: =D13 -> 45938
C40: Business description:
C41: Secured, convertible debenture
C42: A blueberry farm located in Marondera

Sheet Solgas $5m
C6: Counterparty | D6: Solgas
C7: Principal | D7: 5000000.1
C8: Instrument Type | D8: Bond
C9: Interest Rate | D9: 0.075
C10: Interest Pmt Fequency | D10: Semi-annually
C11: Unpaid Interest Accrued to 31 December 2024 | D11: 2090916.6 | E11: Accrued but unpaid ( Assumed it will be paid equally in the remaining coupon dates)
C12: Maturity Date | D12: =D13+365*7 -> 46156
C13: Issue Date | D13: 43601
C14: Next Coupon Payment Date | D14: =I21 -> 45791
C15: Valuation Date | D15: 45657
C16: Solar companies credit spread | D16: ='Market Inputs '!H5 -> 0.0296 | E16: Bloomberg
C17: Country risk premium | D17: ='Market Inputs '!H9 -> 0.1202 | E17: http://pages.stern.nyu.edu/~adamodar/New_Home_Page/datafile/ctryprem.html
C19: Term | D19: Interpolated Nelson Seigel-Svenson | E19: Discount rate | F19: CF | G19: PVIF | H19: PV | I19: Coupon dates | J19: Interest | K19: Accrued Interest | L19: Accrued Interest | M19: Principal | N19: Balance
C20: =(I20-$D$15)/365 -> 0 | I20: =D15 -> 45657 | L20: =D11 -> 2090916.6 | N20: =D7 -> 5000000.1
C21: =(I21-$D$15)/365 -> 0.36712329 | D21: 0.041768374 | E21: =$D$17+$D$16+D21 -> 0.19156837 | F21: =SUM(J21,K21,M21) -> 2558882 | G21: =1/(1+E21)^(C21) -> 0.93768065 | H21: =F21*G21 -> 2399414.1 | I21: =WORKDAY(C38-1, 1, 'Market Inputs '!$B$23:$B$36) -> 45791 | J21: =(I21-I20)/365*$D$9*(N20+L20) -> 195243.05 | K21: =$D$11/3 -> 696972.21 | L21: =L20-K21 -> 1393944.4 | M21: =$N$20/3 -> 1666666.7 | N21: =N20-M21 -> 3333333.4
C22: =(I22-$D$15)/365 -> 0.86575342 | D22: 0.041606048 | E22: =$D$17+$D$16+D22 -> 0.19140605 | F22: =SUM(J22,K22,M22) -> 2540426.2 | G22: =1/(1+E22)^(C22) -> 0.85931218 | H22: =F22*G22 -> 2183019.1 | I22: =WORKDAY(C39-1, 1, 'Market Inputs '!$B$23:$B$36) -> 45973 | J22: =(I22-I21)/365*$D$9*(N21+L21) -> 176787.24 | K22: =$D$11/3 -> 696972.21 | L22: =L21-K22 -> 696972.21 | M22: =$N$20/3 -> 1666666.7 | N22: =N21-M22 -> 1666666.7
C23: =(I23-$D$15)/365 -> 1.3671233 | D23: 0.041460192 | E23: =$D$17+$D$16+D23 -> 0.19126019 | F23: =SUM(J23,K23,M23) -> 2452518.2 | G23: =1/(1+E23)^(C23) -> 0.78720812 | H23: =F23*G23 -> 1930642.3 | I23: =WORKDAY(C40-1, 1, 'Market Inputs '!$B$23:$B$36) -> 46156 | J23: =(I23-I22)/365*$D$9*(N22+L22) -> 88879.299 | K23: =$D$11/3 -> 696972.21 | L23: =L22-K23 -> 0 | M23: =$N$20/3 -> 1666666.7 | N23: =N22-M23 -> 0
C27: Present Value | D27: =SUM(H21:H23) -> 6513075.5
C28: Carrying Value | D28: =D7+D11 -> 7090916.8
C29: Impairment | D29: =D27-D28 -> -577841.24
D31: USD | E31: Exch rate | F31: ZwG
C32: Fair value | D32: =D27 -> 6513075.5 | E32: ='Market Inputs '!H8 -> 25.7985 | F32: =D32*E32 -> 1.6802758e+08
C33: Carrying value | D33: =D28 -> 7090916.8 | E33: ='Market Inputs '!H8 -> 25.7985 | F33: =E33*D33 -> 1.8293502e+08
C34: Impairment | F34: =F32-F33 -> -14907437
C37: Interest payment dates
C38: =C39-365/2 -> 45791
C39: =C40-365/2 -> 45973.5
C40: =D12 -> 46156

Sheet Solgas $518k
C7: Counterparty | D7: Solgas
C8: Principal | D8: 518288
C9: Instrument Type | D9: Bond
C10: Interest Rate | D10: 0.12
C11: Interest Pmt Fequency | D11: Semi-annually
C12: ='[2]Solgas $5m'!A12 -> Unpaid Interest Accrued to 31 December 2024 | D12: 112803.53 | E12: Accrued but unpaid ( Assumed it will be paid equally in the remaining coupon dates)
C13: Maturity Date | D13: =D14+(365*7) -> 46836
C14: Issue Date | D14: 44281
C15: Next Coupon Payment Date | D15: =I24 -> 45741
C16: Valuation Date | D16: 45657
C17: Future Interest payment Dates | D17: =I24 -> 45741
C18: Solar companies credit spread | D18: ='Market Inputs '!H5 -> 0.0296 | E18: Bloomberg
C19: Country risk premium | D19: ='Market Inputs '!H9 -> 0.1202 | E19: http://pages.stern.nyu.edu/~adamodar/New_Home_Page/datafile/ctryprem.html
C22: Term | D22: Interpolated Nelson Seigel-Svenson | E22: Discount rate | F22: CF | G22: PVIF | H22: PV | I22: Coupon dates | J22: Interest | K22: Accrued Interest Paid | L22: Accrued Interest Balance | M22: Principal | N22: Balance
I23: =D16 -> 45657 | L23: =D12 -> 112803.53 | N23: =D8 -> 518288
C24: =(I24-$D$16)/365 -> 0.23013699 | D24: 0.041816233 | E24: =$D$19+$D$18+D24 -> 0.19161623 | F24: =SUM(J24,K24,M24) -> 107584.43 | G24: =1/(1+E24)^(C24) -> 0.9604576 | H24: =F24*G24 -> 103330.29 | I24: =WORKDAY(C45-1, 1, 'Market Inputs '!$B$23:$B$36) -> 45741 | J24: =(I24-I23)/365*$D$10*(N23+L23) -> 17428.5 | K24: =$D$12/7 -> 16114.79 | L24: =L23-K24 -> 96688.74 | M24: =$N$23/7 -> 74041.143 | N24: =N23-M24 -> 444246.86
C25: =(I25-$D$16)/365 -> 0.72876712 | D25: 0.04164885 | E25: =$D$19+$D$18+D25 -> 0.19144885 | F25: =SUM(J25,K25,M25) -> 122523.15 | G25: =1/(1+E25)^(C25) -> 0.88015416 | H25: =F25*G25 -> 107839.26 | I25: =WORKDAY(C46-1, 1, 'Market Inputs '!$B$23:$B$36) -> 45923 | J25: =(I25-I24)/365*$D$10*(N24+L24) -> 32367.215 | K25: =$D$12/7 -> 16114.79 | L25: =L24-K25 -> 80573.95 | M25: =$N$23/7 -> 74041.143 | N25: =N24-M25 -> 370205.71
C26: =(I26-$D$16)/365 -> 1.230137 | D26: 0.041498417 | E26: =$D$19+$D$18+D26 -> 0.19129842 | F26: =SUM(J26,K26,M26) -> 117276.81 | G26: =1/(1+E26)^(C26) -> 0.80627704 | H26: =F26*G26 -> 94557.602 | I26: =WORKDAY(C47-1, 1, 'Market Inputs '!$B$23:$B$36) -> 46106 | J26: =(I26-I25)/365*$D$10*(N25+L25) -> 27120.881 | K26: =$D$12/7 -> 16114.79 | L26: =L25-K26 -> 64459.16 | M26: =$N$23/7 -> 74041.143 | N26: =N25-M26 -> 296164.57
C27: =(I27-$D$16)/365 -> 1.7287671 | D27: 0.0413648 | E27: =$D$19+$D$18+D27 -> 0.1911648 | F27: =SUM(J27,K27,M27) -> 111734.08 | G27: =1/(1+E27)^(C27) -> 0.7390305 | H27: =F27*G27 -> 82574.89 | I27: =WORKDAY(C48-1, 1, 'Market Inputs '!$B$23:$B$36) -> 46288 | J27: =(I27-I26)/365*$D$10*(N26+L26) -> 21578.143 | K27: =$D$12/7 -> 16114.79 | L27: =L26-K27 -> 48344.37 | M27: =$N$23/7 -> 74041.143 | N27: =N26-M27 -> 222123.43
C28: =(I28-$D$16)/365 -> 2.230137 | D28: 0.041244907 | E28: =$D$19+$D$18+D28 -> 0.19104491 | F28: =SUM(J28,K28,M28) -> 106428.46 | G28: =1/(1+E28)^(C28) -> 0.67712657 | H28: =F28*G28 -> 72065.539 | I28: =WORKDAY(C49-1, 1, 'Market Inputs '!$B$23:$B$36) -> 46471 | J28: =(I28-I27)/365*$D$10*(N27+L27) -> 16272.528 | K28: =$D$12/7 -> 16114.79 | L28: =L27-K28 -> 32229.58 | M28: =$N$23/7 -> 74041.143 | N28: =N27-M28 -> 148082.29
C29: =(I29-$D$16)/365 -> 2.7287671 | D29: 0.041138592 | E29: =$D$19+$D$18+D29 -> 0.19093859 | F29: =SUM(J29,K29,M29) -> 100945 | G29: =1/(1+E29)^(C29) -> 0.62074837 | H29: =F29*G29 -> 62661.447 | I29: =WORKDAY(C50-1, 1, 'Market Inputs '!$B$23:$B$36) -> 46653 | J29: =(I29-I28)/365*$D$10*(N28+L28) -> 10789.072 | K29: =$D$12/7 -> 16114.79 | L29: =L28-K29 -> 16114.79 | M29: =$N$23/7 -> 74041.143 | N29: =N28-M29 -> 74041.143
C30: =(I30-$D$16)/365 -> 3.230137 | D30: 0.041043357 | E30: =$D$19+$D$18+D30 -> 0.19084336 | F30: =SUM(J30,K30,M30) -> 95580.109 | G30: =1/(1+E30)^(C30) -> 0.56882559 | H30: =F30*G30 -> 54368.412 | I30: =WORKDAY(C51-1, 1, 'Market Inputs '!$B$23:$B$36) -> 46836 | J30: =(I30-I29)/365*$D$10*(N29+L29) -> 5424.1761 | K30: =$D$12/7 -> 16114.79 | L30: =L29-K30 -> 0 | M30: =$N$23/7 -> 74041.143 | N30: =N29-M30 -> 0
C33: Present Value | D33: =SUM(H24:H30) -> 577397.43
C34: Carrying Value | D34: =D8+D12 -> 631091.53
C35: Impairment | D35: =D33-D34 -> -53694.096
D38: USD | E38: Exch rate | F38: ZwG
C39: Fair value | D39: =D33 -> 577397.43 | E39: ='Market Inputs '!H8 -> 25.7985 | F39: =D39*E39 -> 14895988
C40: Carrying value | D40: =D34 -> 631091.53 | E40: =E39 -> 25.7985 | F40: =E40*D40 -> 16281215
C41: Impairment | F41: =F39-F40 -> -1385227.1
C44: Interest Payment Dates
C45: =C46-365/2 -> 45741
C46: =C47-365/2 -> 45923.5
C47: =C48-365/2 -> 46106
C48: =C49-365/2 -> 46288.5
C49: =C50-365/2 -> 46471
C50: =C51-365/2 -> 46653.5
C51: =D13 -> 46836

Sheet Glytime 
C6: Counterparty | D6: Glytime
C7: Principal | D7: 900000.08
C8: Instrument Type | D8: Bond
C9: Interest Rate | D9: 0.12
C10: Interest Pmt Fequency | D10: Semi-annually
C11: ='[1]Richaw $5m'!A12 -> Interest Accrued to 31 December 2024 | D11: 99544.88 | E11: Accrued but unpaid ( Assumed it will be paid equally in the remaining coupon dates)
C12: Maturity Date | D12: =D13+(5*365) -> 47065
C13: Issue Date | D13: 45240
C14: Next Coupon Payment Date | D14: =I22 -> 45789
C15: Valuation Date | D15: 45657
C16: Solar companies credit spread | D16: ='Market Inputs '!H5 -> 0.0296 | E16: Bloomberg
C17: Country risk premium | D17: ='Market Inputs '!H9 -> 0.1202 | E17: http://pages.stern.nyu.edu/~adamodar/New_Home_Page/datafile/ctryprem.html
C20: Term | D20: Interpolated Nelson Seigel-Svenson | E20: Discount rate | F20: CF | G20: PVIF | H20: PV | I20: Coupon dates | J20: Interest | K20: Accrued Interest Paid | L20: Accrued Interest Balance | M20: Principal | N20: Balance
C21: =(I21-$D$15)/365 -> 0 | I21: =D15 -> 45657 | L21: =D11 -> 99544.88 | N21: =D7 -> 900000.08
C22: =(I22-$D$15)/365 -> 0.36164384 | D22: 0.04177026 | E22: =$D$17+$D$16+D22 -> 0.19157026 | F22: =SUM(J22,K22,M22) -> 168320.63 | G22: =1/(1+E22)^(C22) -> 0.93858108 | H22: =F22*G22 -> 157982.56 | I22: =WORKDAY(C45-1, 1, 'Market Inputs '!$B$23:$B$36) -> 45789 | J22: =(I22-I21)/365*$D$9*(N21+L21) -> 43377.513 | K22: =$D$11/8 -> 12443.11 | L22: =L21-K22 -> 87101.77 | M22: =$N$21/8 -> 112500.01 | N22: =N21-M22 -> 787500.07
C23: =(I23-$D$15)/365 -> 0.86027397 | D23: 0.041607735 | E23: =$D$17+$D$16+D23 -> 0.19140773 | F23: =SUM(J23,K23,M23) -> 177275.46 | G23: =1/(1+E23)^(C23) -> 0.86013616 | H23: =F23*G23 -> 152481.03 | I23: =WORKDAY(C46-1, 1, 'Market Inputs '!$B$23:$B$36) -> 45971 | J23: =(I23-I22)/365*$D$9*(N22+L22) -> 52332.34 | K23: =$D$11/8 -> 12443.11 | L23: =L22-K23 -> 74658.66 | M23: =$N$21/8 -> 112500.01 | N23: =N22-M23 -> 675000.06
C24: =(I24-$D$15)/365 -> 1.3589041 | D24: 0.041462452 | E24: =$D$17+$D$16+D24 -> 0.19126245 | F24: =SUM(J24,K24,M24) -> 169799.41 | G24: =1/(1+E24)^(C24) -> 0.78833927 | H24: =F24*G24 -> 133859.54 | I24: =WORKDAY(C47-1, 1, 'Market Inputs '!$B$23:$B$36) -> 46153 | J24: =(I24-I23)/365*$D$9*(N23+L23) -> 44856.292 | K24: =$D$11/8 -> 12443.11 | L24: =L23-K24 -> 62215.55 | M24: =$N$21/8 -> 112500.01 | N24: =N23-M24 -> 562500.05
C25: =(I25-$D$15)/365 -> 1.8575342 | D25: 0.041332686 | E25: =$D$17+$D$16+D25 -> 0.19113269 | F25: =SUM(J25,K25,M25) -> 162323.36 | G25: =1/(1+E25)^(C25) -> 0.72260579 | H25: =F25*G25 -> 117295.8 | I25: =WORKDAY(C48-1, 1, 'Market Inputs '!$B$23:$B$36) -> 46335 | J25: =(I25-I24)/365*$D$9*(N24+L24) -> 37380.243 | K25: =$D$11/8 -> 12443.11 | L25: =L24-K25 -> 49772.44 | M25: =$N$21/8 -> 112500.01 | N25: =N24-M25 -> 450000.04
C26: =(I26-$D$15)/365 -> 2.3561644 | D26: 0.041216874 | E26: =$D$17+$D$16+D26 -> 0.19101687 | F26: =SUM(J26,K26,M26) -> 154847.31 | G26: =1/(1+E26)^(C26) -> 0.662407 | H26: =F26*G26 -> 102571.95 | I26: =WORKDAY(C49-1, 1, 'Market Inputs '!$B$23:$B$36) -> 46517 | J26: =(I26-I25)/365*$D$9*(N25+L25) -> 29904.194 | K26: =$D$11/8 -> 12443.11 | L26: =L25-K26 -> 37329.33 | M26: =$N$21/8 -> 112500.01 | N26: =N25-M26 -> 337500.03
C27: =(I27-$D$15)/365 -> 2.8575342 | D27: 0.041113066 | E27: =$D$17+$D$16+D27 -> 0.19091307 | F27: =SUM(J27,K27,M27) -> 147494.5 | G27: =1/(1+E27)^(C27) -> 0.60697406 | H27: =F27*G27 -> 89525.334 | I27: =WORKDAY(C50-1, 1, 'Market Inputs '!$B$23:$B$36) -> 46700 | J27: =(I27-I26)/365*$D$9*(N26+L26) -> 22551.377 | K27: =$D$11/8 -> 12443.11 | L27: =L26-K27 -> 24886.22 | M27: =$N$21/8 -> 112500.01 | N27: =N26-M27 -> 225000.02
C28: =(I28-$D$15)/365 -> 3.3561644 | D28: 0.041021113 | E28: =$D$17+$D$16+D28 -> 0.19082111 | F28: =SUM(J28,K28,M28) -> 139895.22 | G28: =1/(1+E28)^(C28) -> 0.5564762 | H28: =F28*G28 -> 77848.358 | I28: =WORKDAY(C51-1, 1, 'Market Inputs '!$B$23:$B$36) -> 46882 | J28: =(I28-I27)/365*$D$9*(N27+L27) -> 14952.097 | K28: =$D$11/8 -> 12443.11 | L28: =L27-K28 -> 12443.11 | M28: =$N$21/8 -> 112500.01 | N28: =N27-M28 -> 112500.01
C29: =(I29-$D$15)/365 -> 3.8575342 | D29: 0.040938833 | E29: =$D$17+$D$16+D29 -> 0.19073883 | F29: =SUM(J29,K29,M29) -> 132460.25 | G29: =1/(1+E29)^(C29) -> 0.50995892 | H29: =F29*G29 -> 67549.283 | I29: =WORKDAY(C52-1, 1, 'Market Inputs '!$B$23:$B$36) -> 47065 | J29: =(I29-I28)/365*$D$9*(N28+L28) -> 7517.1258 | K29: =$D$11/8 -> 12443.11 | L29: =L28-K29 -> 0 | M29: =$N$21/8 -> 112500.01 | N29: =N28-M29 -> 0
C32: Present Value | D32: =SUM(H22:H29) -> 899113.86
C33: Carrying Value | D33: =D7+D11 -> 999544.96
C34: Impairment | D34: =D32-D33 -> -100431.1
D36: USD | E36: Exch rate | F36: ZwG
C37: Fair value | D37: =D32 -> 899113.86 | E37: ='Market Inputs '!H8 -> 25.7985 | F37: =D37*E37 -> 23195789
C38: Carrying value | D38: =D33 -> 999544.96 | E38: ='Market Inputs '!H8 -> 25.7985 | F38: =D38*E38 -> 25786761
F39: =F37-F38 -> -2590971.7
C42: Interest Payment Dates
C43: =D13+(365/2) -> 45422.5
C44: =C43+(365/2) -> 45605
C45: =C44+(365/2) -> 45787.5
C46: =C45+(365/2) -> 45970
C47: =C46+(365/2) -> 46152.5
C48: =C47+(365/2) -> 46335
C49: =C48+(365/2) -> 46517.5
C50: =C49+(365/2) -> 46700
C51: =C50+(365/2) -> 46882.5
C52: =C51+(365/2) -> 47065

Sheet Zimcampus
C6: Counterparty | D6: Zimcampus
C7: Principal | D7: 200000
C8: Instrument Type | D8: Debt
C9: Interest Rate | D9: 0.1
C10: Interest Pmt Fequency | D10: Semi-annually
C11: ='[1]Richaw $5m'!A12 -> Interest Accrued to 31 December 2024 | D11: 3068.49 | E11: Accrued but unpaid ( Assumed it will be paid equally in the remaining coupon dates)
C12: Maturity Date | D12: =D13+(0.5*365) -> 45783.5
C13: Issue Date | D13: 45601
C14: Next Coupon Payment Date | D14: =D12 -> 45783.5
C15: Valuation Date | D15: 45657
C16: Solar companies credit spread | D16: ='Market Inputs '!H5 -> 0.0296 | E16: Bloomberg
C17: Country risk premium | D17: ='Market Inputs '!H9 -> 0.1202 | E17: http://pages.stern.nyu.edu/~adamodar/New_Home_Page/datafile/ctryprem.html
C20: Term | D20: Interpolated Nelson Seigel-Svenson | E20: Discount rate | F20: CF | G20: PVIF | H20: PV | I20: Coupon dates | J20: Interest | K20: Accrued Interest Paid | L20: Accrued Interest Balance | M20: Principal | N20: Balance
C21: =(I21-$D$15)/365 -> 0 | I21: =D15 -> 45657 | L21: =D11 -> 3068.49 | N21: =D7 -> 200000
C22: =(I22-$D$15)/365 -> 0.34520548 | D22: 0.041775933 | E22: =$D$17+$D$16+D22 -> 0.19157593 | F22: =SUM(J22,K22,M22) -> 210078.53 | G22: =1/(1+E22)^(C22) -> 0.94128766 | H22: =F22*G22 -> 197744.32 | I22: =WORKDAY(D12-1, 1, 'Market Inputs '!$B$23:$B$36) -> 45783 | J22: =(I22-I21)/365*$D$9*(N21+L21) -> 7010.0355 | K22: =D11/1 -> 3068.49 | L22: =L21-K22 -> 0 | M22: =$N$21 -> 200000 | N22: =N21-M22 -> 0
C25: Present Value | D25: =SUM(H22) -> 197744.32
C26: Carrying Value | D26: =D7+D11 -> 203068.49
C27: Impairment | D27: =D25-D26 -> -5324.1668
D30: USD | E30: Exch rate | F30: ZwG
C31: Fair value | D31: =D25 -> 197744.32 | E31: ='Market Inputs '!H8 -> 25.7985 | F31: =D31*E31 -> 5101506.9
C32: Carrying value | D32: =D26 -> 203068.49 | E32: =E31 -> 25.7985 | F32: =D32*E32 -> 5238862.4
F33: =F31-F32 -> -137355.52
C36: Key Assumptions
C37: * The loan will mature in 6 months and the coupon will be paid on maturity of the loan facility (bullet payment)
